Workbook

Sheet Read Me
A1: NIST SP 800-171 Rev 3: Measurement Register
A2: What gets measured: requirements, organization-defined parameters (ODPs), and the SP 800-171A Rev 3 assessment objectives. Generic and blank: not applied to any organization.
A4: SHEETS
A5: Summary | B5: Live totals by family: objectives met / not met / not assessed, and how many ODPs are defined. Nothing to type here.
A6: Requirements | B6: The 97 Rev 3 requirements with NIST's requirement text. Fill in owner, status, evidence location. Rev 2 ID column is empty on purpose (see Limits).
A7: ODPs | B7: The 88 organization-defined parameters. These are the blanks NIST leaves for each organization (time periods, frequencies, events). Define these FIRST.
A8: Objectives | B8: The 422 assessment objectives from SP 800-171A Rev 3. This is the list of things that actually get measured, one row each.
A9: Methods | B9: For each requirement, what NIST suggests you examine, whom you interview, and what you test.
A10: Withdrawn | B10: 33 numbers that Rev 3 keeps as placeholders, and where NIST says each one went. They have no objectives.
A12: HOW TO USE IT
A13: Step 1 | B13: Go to ODPs. For each row, type the value your organization chooses, who decided it, the date, and why. Set Status to Defined. Many objectives cannot be judged until their ODP is defined.
A14: Step 2 | B14: Go to Objectives. For each row, set Result (Met / Not Met / N/A), the Method you used, and where the evidence is kept. The 'Depends on ODP(s)' column tells you which ODP to check first.
A15: Step 3 | B15: Go to Requirements to record an owner and an overall implementation status for each requirement.
A16: Step 4 | B16: Look at Summary to see progress by family.
A18: COLOR LEGEND
A19: Dark blue header | B19: NIST data. Please do not edit these columns.
A20: Gold header, yellow cells | B20: Yours to fill in. Cells turn green when Met / Defined / Implemented, red for Not Met, grey for N/A. Yellow means still waiting for you.
A22: EXAMPLE ROWS
A23: Shown for format only | B23: These two examples use made-up values. They are not NIST values and not a recommendation. They are NOT in the data sheets.
A24: ODPs sheet | B24: ODP ID: A.03.01.01.ODP[01] | Value defined: 90 days | Decided by: ISSO | Date decided: 2026-10-05 | Basis: example only | Status: Defined
A25: Objectives sheet | B25: Objective ID: A.03.01.01.f.02 | Result: Met | Method used: Test | Evidence reference: example: screenshot of the directory's inactivity setting | Assessor: example | Date assessed: 2026-10-05
A27: SOURCE AND CHECKS
A28: Source | B28: NIST's OSCAL digital edition of SP 800-171 Rev 3 with SP 800-171A Rev 3 (github.com/usnistgov/oscal-content, nist.gov/SP800-171/rev3). Catalog version 1.1.0, dated 2026-05-12; repository commit 78650f0. Pulled 2026-10-05.
A29: Counts checked | B29: 97 requirements in 17 families; 88 ODPs; 422 assessment objectives; 281 method entries; 33 withdrawn numbers. The Summary totals should show the same numbers.
A30: Text handling | B30: Where NIST's text has a blank for an ODP, this workbook shows it as [ODP ID: parameter type] so you can see exactly where each value plugs in.
A32: LIMITS
A33: Rev 2 crosswalk | B33: The Rev 2 ID(s) column on Requirements is empty. NIST's Rev 2 to Rev 3 mapping is not in the OSCAL data; it still needs to be pulled and added.
A34: Not included | B34: NIST's discussion text and references for each requirement are left out to keep the sheets readable. The full publication has them.
A35: Not a legal reading | B35: This is a working tool built from NIST's data. It does not say which Rev, class deviation, or contract clause applies to any organization.

Sheet Summary
A1: Progress summary
A2: Updates by itself from the Objectives and ODPs sheets. Nothing to type on this sheet.
A4: Family | B4: Requirements | C4: Objectives | D4: Met | E4: Not Met | F4: N/A | G4: Not assessed | H4: % assessed | I4: ODPs | J4: ODPs defined | K4: % ODPs defined
A5: Access Control | B5: =COUNTIF(Requirements!$A$2:$A$98,A5) -> 16 | C5: =COUNTIF(Objectives!$B$2:$B$423,A5) -> 74 | D5: =COUNTIFS(Objectives!$B$2:$B$423,A5,Objectives!$H$2:$H$423,"Met") -> 0 | E5: =COUNTIFS(Objectives!$B$2:$B$423,A5,Objectives!$H$2:$H$423,"Not Met") -> 0 | F5: =COUNTIFS(Objectives!$B$2:$B$423,A5,Objectives!$H$2:$H$423,"N/A") -> 0 | G5: =COUNTIFS(Objectives!$B$2:$B$423,A5,Objectives!$H$2:$H$423,"Not assessed") -> 74 | H5: =IF(C5=0,0,(D5+E5+F5)/C5) -> 0 | I5: =COUNTIF(ODPs!$B$2:$B$89,A5) -> 18 | J5: =COUNTIFS(ODPs!$B$2:$B$89,A5,ODPs!$M$2:$M$89,"Defined") -> 0 | K5: =IF(I5=0,"none",J5/I5) -> 0
A6: Awareness and Training | B6: =COUNTIF(Requirements!$A$2:$A$98,A6) -> 2 | C6: =COUNTIF(Objectives!$B$2:$B$423,A6) -> 17 | D6: =COUNTIFS(Objectives!$B$2:$B$423,A6,Objectives!$H$2:$H$423,"Met") -> 0 | E6: =COUNTIFS(Objectives!$B$2:$B$423,A6,Objectives!$H$2:$H$423,"Not Met") -> 0 | F6: =COUNTIFS(Objectives!$B$2:$B$423,A6,Objectives!$H$2:$H$423,"N/A") -> 0 | G6: =COUNTIFS(Objectives!$B$2:$B$423,A6,Objectives!$H$2:$H$423,"Not assessed") -> 17 | H6: =IF(C6=0,0,(D6+E6+F6)/C6) -> 0 | I6: =COUNTIF(ODPs!$B$2:$B$89,A6) -> 8 | J6: =COUNTIFS(ODPs!$B$2:$B$89,A6,ODPs!$M$2:$M$89,"Defined") -> 0 | K6: =IF(I6=0,"none",J6/I6) -> 0
A7: Audit and Accountability | B7: =COUNTIF(Requirements!$A$2:$A$98,A7) -> 8 | C7: =COUNTIF(Objectives!$B$2:$B$423,A7) -> 30 | D7: =COUNTIFS(Objectives!$B$2:$B$423,A7,Objectives!$H$2:$H$423,"Met") -> 0 | E7: =COUNTIFS(Objectives!$B$2:$B$423,A7,Objectives!$H$2:$H$423,"Not Met") -> 0 | F7: =COUNTIFS(Objectives!$B$2:$B$423,A7,Objectives!$H$2:$H$423,"N/A") -> 0 | G7: =COUNTIFS(Objectives!$B$2:$B$423,A7,Objectives!$H$2:$H$423,"Not assessed") -> 30 | H7: =IF(C7=0,0,(D7+E7+F7)/C7) -> 0 | I7: =COUNTIF(ODPs!$B$2:$B$89,A7) -> 6 | J7: =COUNTIFS(ODPs!$B$2:$B$89,A7,ODPs!$M$2:$M$89,"Defined") -> 0 | K7: =IF(I7=0,"none",J7/I7) -> 0
A8: Configuration Management | B8: =COUNTIF(Requirements!$A$2:$A$98,A8) -> 10 | C8: =COUNTIF(Objectives!$B$2:$B$423,A8) -> 49 | D8: =COUNTIFS(Objectives!$B$2:$B$423,A8,Objectives!$H$2:$H$423,"Met") -> 0 | E8: =COUNTIFS(Objectives!$B$2:$B$423,A8,Objectives!$H$2:$H$423,"Not Met") -> 0 | F8: =COUNTIFS(Objectives!$B$2:$B$423,A8,Objectives!$H$2:$H$423,"N/A") -> 0 | G8: =COUNTIFS(Objectives!$B$2:$B$423,A8,Objectives!$H$2:$H$423,"Not assessed") -> 49 | H8: =IF(C8=0,0,(D8+E8+F8)/C8) -> 0 | I8: =COUNTIF(ODPs!$B$2:$B$89,A8) -> 12 | J8: =COUNTIFS(ODPs!$B$2:$B$89,A8,ODPs!$M$2:$M$89,"Defined") -> 0 | K8: =IF(I8=0,"none",J8/I8) -> 0
A9: Identification and Authentication | B9: =COUNTIF(Requirements!$A$2:$A$98,A9) -> 8 | C9: =COUNTIF(Objectives!$B$2:$B$423,A9) -> 36 | D9: =COUNTIFS(Objectives!$B$2:$B$423,A9,Objectives!$H$2:$H$423,"Met") -> 0 | E9: =COUNTIFS(Objectives!$B$2:$B$423,A9,Objectives!$H$2:$H$423,"Not Met") -> 0 | F9: =COUNTIFS(Objectives!$B$2:$B$423,A9,Objectives!$H$2:$H$423,"N/A") -> 0 | G9: =COUNTIFS(Objectives!$B$2:$B$423,A9,Objectives!$H$2:$H$423,"Not assessed") -> 36 | H9: =IF(C9=0,0,(D9+E9+F9)/C9) -> 0 | I9: =COUNTIF(ODPs!$B$2:$B$89,A9) -> 8 | J9: =COUNTIFS(ODPs!$B$2:$B$89,A9,ODPs!$M$2:$M$89,"Defined") -> 0 | K9: =IF(I9=0,"none",J9/I9) -> 0
A10: Incident Response | B10: =COUNTIF(Requirements!$A$2:$A$98,A10) -> 5 | C10: =COUNTIF(Objectives!$B$2:$B$423,A10) -> 29 | D10: =COUNTIFS(Objectives!$B$2:$B$423,A10,Objectives!$H$2:$H$423,"Met") -> 0 | E10: =COUNTIFS(Objectives!$B$2:$B$423,A10,Objectives!$H$2:$H$423,"Not Met") -> 0 | F10: =COUNTIFS(Objectives!$B$2:$B$423,A10,Objectives!$H$2:$H$423,"N/A") -> 0 | G10: =COUNTIFS(Objectives!$B$2:$B$423,A10,Objectives!$H$2:$H$423,"Not assessed") -> 29 | H10: =IF(C10=0,0,(D10+E10+F10)/C10) -> 0 | I10: =COUNTIF(ODPs!$B$2:$B$89,A10) -> 7 | J10: =COUNTIFS(ODPs!$B$2:$B$89,A10,ODPs!$M$2:$M$89,"Defined") -> 0 | K10: =IF(I10=0,"none",J10/I10) -> 0
A11: Maintenance | B11: =COUNTIF(Requirements!$A$2:$A$98,A11) -> 3 | C11: =COUNTIF(Objectives!$B$2:$B$423,A11) -> 16 | D11: =COUNTIFS(Objectives!$B$2:$B$423,A11,Objectives!$H$2:$H$423,"Met") -> 0 | E11: =COUNTIFS(Objectives!$B$2:$B$423,A11,Objectives!$H$2:$H$423,"Not Met") -> 0 | F11: =COUNTIFS(Objectives!$B$2:$B$423,A11,Objectives!$H$2:$H$423,"N/A") -> 0 | G11: =COUNTIFS(Objectives!$B$2:$B$423,A11,Objectives!$H$2:$H$423,"Not assessed") -> 16 | H11: =IF(C11=0,0,(D11+E11+F11)/C11) -> 0 | I11: =COUNTIF(ODPs!$B$2:$B$89,A11) -> 0 | J11: =COUNTIFS(ODPs!$B$2:$B$89,A11,ODPs!$M$2:$M$89,"Defined") -> 0 | K11: =IF(I11=0,"none",J11/I11) -> none
A12: Media Protection | B12: =COUNTIF(Requirements!$A$2:$A$98,A12) -> 7 | C12: =COUNTIF(Objectives!$B$2:$B$423,A12) -> 15 | D12: =COUNTIFS(Objectives!$B$2:$B$423,A12,Objectives!$H$2:$H$423,"Met") -> 0 | E12: =COUNTIFS(Objectives!$B$2:$B$423,A12,Objectives!$H$2:$H$423,"Not Met") -> 0 | F12: =COUNTIFS(Objectives!$B$2:$B$423,A12,Objectives!$H$2:$H$423,"N/A") -> 0 | G12: =COUNTIFS(Objectives!$B$2:$B$423,A12,Objectives!$H$2:$H$423,"Not assessed") -> 15 | H12: =IF(C12=0,0,(D12+E12+F12)/C12) -> 0 | I12: =COUNTIF(ODPs!$B$2:$B$89,A12) -> 1 | J12: =COUNTIFS(ODPs!$B$2:$B$89,A12,ODPs!$M$2:$M$89,"Defined") -> 0 | K12: =IF(I12=0,"none",J12/I12) -> 0
A13: Personnel Security | B13: =COUNTIF(Requirements!$A$2:$A$98,A13) -> 2 | C13: =COUNTIF(Objectives!$B$2:$B$423,A13) -> 9 | D13: =COUNTIFS(Objectives!$B$2:$B$423,A13,Objectives!$H$2:$H$423,"Met") -> 0 | E13: =COUNTIFS(Objectives!$B$2:$B$423,A13,Objectives!$H$2:$H$423,"Not Met") -> 0 | F13: =COUNTIFS(Objectives!$B$2:$B$423,A13,Objectives!$H$2:$H$423,"N/A") -> 0 | G13: =COUNTIFS(Objectives!$B$2:$B$423,A13,Objectives!$H$2:$H$423,"Not assessed") -> 9 | H13: =IF(C13=0,0,(D13+E13+F13)/C13) -> 0 | I13: =COUNTIF(ODPs!$B$2:$B$89,A13) -> 2 | J13: =COUNTIFS(ODPs!$B$2:$B$89,A13,ODPs!$M$2:$M$89,"Defined") -> 0 | K13: =IF(I13=0,"none",J13/I13) -> 0
A14: Physical Protection | B14: =COUNTIF(Requirements!$A$2:$A$98,A14) -> 5 | C14: =COUNTIF(Objectives!$B$2:$B$423,A14) -> 20 | D14: =COUNTIFS(Objectives!$B$2:$B$423,A14,Objectives!$H$2:$H$423,"Met") -> 0 | E14: =COUNTIFS(Objectives!$B$2:$B$423,A14,Objectives!$H$2:$H$423,"Not Met") -> 0 | F14: =COUNTIFS(Objectives!$B$2:$B$423,A14,Objectives!$H$2:$H$423,"N/A") -> 0 | G14: =COUNTIFS(Objectives!$B$2:$B$423,A14,Objectives!$H$2:$H$423,"Not assessed") -> 20 | H14: =IF(C14=0,0,(D14+E14+F14)/C14) -> 0 | I14: =COUNTIF(ODPs!$B$2:$B$89,A14) -> 4 | J14: =COUNTIFS(ODPs!$B$2:$B$89,A14,ODPs!$M$2:$M$89,"Defined") -> 0 | K14: =IF(I14=0,"none",J14/I14) -> 0
A15: Risk Assessment | B15: =COUNTIF(Requirements!$A$2:$A$98,A15) -> 3 | C15: =COUNTIF(Objectives!$B$2:$B$423,A15) -> 12 | D15: =COUNTIFS(Objectives!$B$2:$B$423,A15,Objectives!$H$2:$H$423,"Met") -> 0 | E15: =COUNTIFS(Objectives!$B$2:$B$423,A15,Objectives!$H$2:$H$423,"Not Met") -> 0 | F15: =COUNTIFS(Objectives!$B$2:$B$423,A15,Objectives!$H$2:$H$423,"N/A") -> 0 | G15: =COUNTIFS(Objectives!$B$2:$B$423,A15,Objectives!$H$2:$H$423,"Not assessed") -> 12 | H15: =IF(C15=0,0,(D15+E15+F15)/C15) -> 0 | I15: =COUNTIF(ODPs!$B$2:$B$89,A15) -> 5 | J15: =COUNTIFS(ODPs!$B$2:$B$89,A15,ODPs!$M$2:$M$89,"Defined") -> 0 | K15: =IF(I15=0,"none",J15/I15) -> 0
A16: Security Assessment and Monitoring | B16: =COUNTIF(Requirements!$A$2:$A$98,A16) -> 4 | C16: =COUNTIF(Objectives!$B$2:$B$423,A16) -> 17 | D16: =COUNTIFS(Objectives!$B$2:$B$423,A16,Objectives!$H$2:$H$423,"Met") -> 0 | E16: =COUNTIFS(Objectives!$B$2:$B$423,A16,Objectives!$H$2:$H$423,"Not Met") -> 0 | F16: =COUNTIFS(Objectives!$B$2:$B$423,A16,Objectives!$H$2:$H$423,"N/A") -> 0 | G16: =COUNTIFS(Objectives!$B$2:$B$423,A16,Objectives!$H$2:$H$423,"Not assessed") -> 17 | H16: =IF(C16=0,0,(D16+E16+F16)/C16) -> 0 | I16: =COUNTIF(ODPs!$B$2:$B$89,A16) -> 3 | J16: =COUNTIFS(ODPs!$B$2:$B$89,A16,ODPs!$M$2:$M$89,"Defined") -> 0 | K16: =IF(I16=0,"none",J16/I16) -> 0
... A21: Supply Chain Risk Management | B21: =COUNTIF(Requirements!$A$2:$A$98,A21) -> 3 | C21: =COUNTIF(Objectives!$B$2:$B$423,A21) -> 22 | D21: =COUNTIFS(Objectives!$B$2:$B$423,A21,Objectives!$H$2:$H$423,"Met") -> 0 | E21: =COUNTIFS(Objectives!$B$2:$B$423,A21,Objectives!$H$2:$H$423,"Not Met") -> 0 | F21: =COUNTIFS(Objectives!$B$2:$B$423,A21,Objectives!$H$2:$H$423,"N/A") -> 0 | G21: =COUNTIFS(Objectives!$B$2:$B$423,A21,Objectives!$H$2:$H$423,"Not assessed") -> 22 | H21: =IF(C21=0,0,(D21+E21+F21)/C21) -> 0 | I21: =COUNTIF(ODPs!$B$2:$B$89,A21) -> 2 | J21: =COUNTIFS(ODPs!$B$2:$B$89,A21,ODPs!$M$2:$M$89,"Defined") -> 0 | K21: =IF(I21=0,"none",J21/I21) -> 0
A22: Total | B22: =SUM(B5:B21) -> 97 | C22: =SUM(C5:C21) -> 422 | D22: =SUM(D5:D21) -> 0 | E22: =SUM(E5:E21) -> 0 | F22: =SUM(F5:F21) -> 0 | G22: =SUM(G5:G21) -> 422 | H22: =IF(C22=0,0,(D22+E22+F22)/C22) -> 0 | I22: =SUM(I5:I21) -> 88 | J22: =SUM(J5:J21) -> 0 | K22: =IF(I22=0,0,J22/I22) -> 0

Sheet Requirements
A1: Family | B1: Req ID | C1: Requirement title | D1: Requirement text (SP 800-171 Rev 3) | E1: ODPs | F1: Objectives | G1: Assessment methods | H1: Rev 2 ID(s) (to fill) | I1: Owner | J1: Implementation status | K1: Evidence location | L1: Notes
A2: Access Control | B2: 03.01.01 | C2: Account Management | D2: a. Define the types of system accounts allowed and prohibited. b. Create, enable, modify, disable, and remove system accounts in accordance with policy, procedures, prerequisites, and criteria. c. Specify: 1. Authorized users of the system, 2. Group and role membership, and 3. Access authorizations (i.e., privileges) for each account. d. Authorize access to the system based on: 1. A valid access authorization and 2. Intended system usage. e. Monitor the use of system accounts. f. Disable system accounts when: 1. The accounts have expired, 2. The accounts have been inactive for [A.03.01.01.ODP[01]: time period], 3. The accounts are no longer associated with a user or individual, 4. The accounts are in violation of organizational policy, or 5. Significant risks associated with individuals are discovered. g. Notify account managers and designated personnel or roles within: 1. [A.03.01.01.ODP[02]: time period] when accounts are no longer required. 2. [A.03.01.01.ODP[03]: time period] when users are terminated or transferred. 3. [A.03.01.01.ODP[04]: time period] when system usage or the need-to-know changes for an individual. h. Require that users log out of the system after [A.03.01.01.ODP[05]: time period] of expected inactivity or when [A.03.01.01.ODP[06]: circumstances]. | E2: =COUNTIF(ODPs!$C$2:$C$89,B2) -> 6 | F2: =COUNTIF(Objectives!$C$2:$C$423,B2) -> 22 | G2: Examine, Interview, Test | J2: Not started
A3: Access Control | B3: 03.01.02 | C3: Access Enforcement | D3: Enforce approved authorizations for logical access to CUI and system resources in accordance with applicable access control policies. | E3: =COUNTIF(ODPs!$C$2:$C$89,B3) -> 0 | F3: =COUNTIF(Objectives!$C$2:$C$423,B3) -> 2 | G3: Examine, Interview, Test | J3: Not started
A4: Access Control | B4: 03.01.03 | C4: Information Flow Enforcement | D4: Enforce approved authorizations for controlling the flow of CUI within the system and between connected systems. | E4: =COUNTIF(ODPs!$C$2:$C$89,B4) -> 0 | F4: =COUNTIF(Objectives!$C$2:$C$423,B4) -> 2 | G4: Examine, Interview, Test | J4: Not started
A5: Access Control | B5: 03.01.04 | C5: Separation of Duties | D5: a. Identify the duties of individuals requiring separation. b. Define system access authorizations to support separation of duties. | E5: =COUNTIF(ODPs!$C$2:$C$89,B5) -> 0 | F5: =COUNTIF(Objectives!$C$2:$C$423,B5) -> 2 | G5: Examine, Interview, Test | J5: Not started
A6: Access Control | B6: 03.01.05 | C6: Least Privilege | D6: a. Allow only authorized system access for users (or processes acting on behalf of users) that is necessary to accomplish assigned organizational tasks. b. Authorize access to [A.03.01.05.ODP[01]: security functions] and [A.03.01.05.ODP[02]: security-relevant information]. c. Review the privileges assigned to roles or classes of users [A.03.01.05.ODP[03]: frequency] to validate the need for such privileges. d. Reassign or remove privileges, as necessary. | E6: =COUNTIF(ODPs!$C$2:$C$89,B6) -> 3 | F6: =COUNTIF(Objectives!$C$2:$C$423,B6) -> 5 | G6: Examine, Interview, Test | J6: Not started
A7: Access Control | B7: 03.01.06 | C7: Least Privilege – Privileged Accounts | D7: a. Restrict privileged accounts on the system to [A.03.01.06.ODP[01]: personnel or roles].. b. Require that users (or roles) with privileged accounts use non-privileged accounts when accessing non-security functions or non-security information. | E7: =COUNTIF(ODPs!$C$2:$C$89,B7) -> 1 | F7: =COUNTIF(Objectives!$C$2:$C$423,B7) -> 2 | G7: Examine, Interview, Test | J7: Not started
A8: Access Control | B8: 03.01.07 | C8: Least Privilege – Privileged Functions | D8: a. Prevent non-privileged users from executing privileged functions. b. Log the execution of privileged functions. | E8: =COUNTIF(ODPs!$C$2:$C$89,B8) -> 0 | F8: =COUNTIF(Objectives!$C$2:$C$423,B8) -> 2 | G8: Examine, Interview, Test | J8: Not started
A9: Access Control | B9: 03.01.08 | C9: Unsuccessful Logon Attempts | D9: a. Enforce a limit of [A.03.01.08.ODP[01]: number] consecutive invalid logon attempts by a user during a [A.03.01.08.ODP[02]: time period]. b. Automatically [A.03.01.08.ODP[03]: SELECTED PARAMETER VALUES] when the maximum number of unsuccessful attempts is exceeded. | E9: =COUNTIF(ODPs!$C$2:$C$89,B9) -> 4 | F9: =COUNTIF(Objectives!$C$2:$C$423,B9) -> 2 | G9: Examine, Interview, Test | J9: Not started
A10: Access Control | B10: 03.01.09 | C10: System Use Notification | D10: Display a system use notification message with privacy and security notices consistent with applicable CUI rules before granting access to the system. | E10: =COUNTIF(ODPs!$C$2:$C$89,B10) -> 0 | F10: =COUNTIF(Objectives!$C$2:$C$423,B10) -> 1 | G10: Examine, Interview, Test | J10: Not started
A11: Access Control | B11: 03.01.10 | C11: Device Lock | D11: a. Prevent access to the system by [A.03.01.10.ODP[01]: SELECTED PARAMETER VALUES]. b. Retain the device lock until the user reestablishes access using established identification and authentication procedures. c. Conceal, via the device lock, information previously visible on the display with a publicly viewable image. | E11: =COUNTIF(ODPs!$C$2:$C$89,B11) -> 2 | F11: =COUNTIF(Objectives!$C$2:$C$423,B11) -> 3 | G11: Examine, Interview, Test | J11: Not started
A12: Access Control | B12: 03.01.11 | C12: Session Termination | D12: Terminate a user session automatically after [A.03.01.11.ODP[01]: conditions or trigger events]. | E12: =COUNTIF(ODPs!$C$2:$C$89,B12) -> 1 | F12: =COUNTIF(Objectives!$C$2:$C$423,B12) -> 1 | G12: Examine, Interview, Test | J12: Not started
A13: Access Control | B13: 03.01.12 | C13: Remote Access | D13: a. Establish usage restrictions, configuration requirements, and connection requirements for each type of allowable remote system access. b. Authorize each type of remote system access prior to establishing such connections. c. Route remote access to the system through authorized and managed access control points. d. Authorize the remote execution of privileged commands and remote access to security-relevant information. | E13: =COUNTIF(ODPs!$C$2:$C$89,B13) -> 0 | F13: =COUNTIF(Objectives!$C$2:$C$423,B13) -> 9 | G13: Examine, Interview, Test | J13: Not started
... A16: Access Control | B16: 03.01.20 | C16: Use of External Systems | D16: a. Prohibit the use of external systems unless the systems are specifically authorized. b. Establish the following security requirements to be satisfied on external systems prior to allowing use of or access to those systems by authorized individuals: [A.03.01.20.ODP[01]: security requirements]. c. Permit authorized individuals to use external systems to access the organizational system or to process, store, or transmit CUI only after: 1. Verifying that the security requirements on the external systems as specified in the organization’s system security plans have been satisfied and 2. Retaining approved system connection or processing agreements with the organizational entities hosting the external systems. d. Restrict the use of organization-controlled portable storage devices by authorized individuals on external systems. | E16: =COUNTIF(ODPs!$C$2:$C$89,B16) -> 1 | F16: =COUNTIF(Objectives!$C$2:$C$423,B16) -> 5 | G16: Examine, Interview, Test | J16: Not started
A17: Access Control | B17: 03.01.22 | C17: Publicly Accessible Content | D17: a. Train authorized individuals to ensure that publicly accessible information does not contain CUI. b. Review the content on publicly accessible systems for CUI and remove such information, if discovered. | E17: =COUNTIF(ODPs!$C$2:$C$89,B17) -> 0 | F17: =COUNTIF(Objectives!$C$2:$C$423,B17) -> 3 | J17: Not started
A18: Awareness and Training | B18: 03.02.01 | C18: Literacy Training and Awareness | D18: a. Provide security literacy training to system users: 1. As part of initial training for new users and [A.03.02.01.ODP[01]: frequency] thereafter, 2. When required by system changes or following [A.03.02.01.ODP[02]: events], and 3. On recognizing and reporting indicators of insider threat, social engineering, and social mining. b. Update security literacy training content [A.03.02.01.ODP[03]: frequency] and following [A.03.02.01.ODP[04]: events]. | E18: =COUNTIF(ODPs!$C$2:$C$89,B18) -> 4 | F18: =COUNTIF(Objectives!$C$2:$C$423,B18) -> 11 | G18: Examine, Interview, Test | J18: Not started
A19: Awareness and Training | B19: 03.02.02 | C19: Role-Based Training | D19: a. Provide role-based security training to organizational personnel: 1. Before authorizing access to the system or CUI, before performing assigned duties, and [A.03.02.02.ODP[01]: frequency] thereafter 2. When required by system changes or following [A.03.02.02.ODP[02]: events]. b. Update role-based training content [A.03.02.02.ODP[03]: frequency] and following [A.03.02.02.ODP[04]: events]. | E19: =COUNTIF(ODPs!$C$2:$C$89,B19) -> 4 | F19: =COUNTIF(Objectives!$C$2:$C$423,B19) -> 6 | G19: Examine, Interview, Test | J19: Not started
A20: Audit and Accountability | B20: 03.03.01 | C20: Event Logging | D20: a. Specify the following event types selected for logging within the system: [A.03.03.01.ODP[01]: event types]. b. Review and update the event types selected for logging [A.03.03.01.ODP[02]: frequency]. | E20: =COUNTIF(ODPs!$C$2:$C$89,B20) -> 2 | F20: =COUNTIF(Objectives!$C$2:$C$423,B20) -> 3 | G20: Examine, Interview, Test | J20: Not started
A21: Audit and Accountability | B21: 03.03.02 | C21: Audit Record Content | D21: a. Include the following content in audit records: 1. What type of event occurred 2. When the event occurred 3. Where the event occurred 4. Source of the event 5. Outcome of the event 6. Identity of the individuals, subjects, objects, or entities associated with the event b. Provide additional information for audit records as needed. | E21: =COUNTIF(ODPs!$C$2:$C$89,B21) -> 0 | F21: =COUNTIF(Objectives!$C$2:$C$423,B21) -> 7 | G21: Examine, Interview, Test | J21: Not started
A22: Audit and Accountability | B22: 03.03.03 | C22: Audit Record Generation | D22: a. Generate audit records for the selected event types and audit record content specified in 03.03.01 and 03.03.02. b. Retain audit records for a time period consistent with the records retention policy. | E22: =COUNTIF(ODPs!$C$2:$C$89,B22) -> 0 | F22: =COUNTIF(Objectives!$C$2:$C$423,B22) -> 2 | G22: Examine, Interview, Test | J22: Not started
A23: Audit and Accountability | B23: 03.03.04 | C23: Response to Audit Logging Process Failures | D23: a. Alert organizational personnel or roles within [A.03.03.04.ODP[01]: time period] in the event of an audit logging process failure. b. Take the following additional actions: [A.03.03.04.ODP[02]: additional actions]. | E23: =COUNTIF(ODPs!$C$2:$C$89,B23) -> 2 | F23: =COUNTIF(Objectives!$C$2:$C$423,B23) -> 2 | G23: Examine, Interview, Test | J23: Not started
A24: Audit and Accountability | B24: 03.03.05 | C24: Audit Record Review, Analysis, and Reporting | D24: a. Review and analyze system audit records [A.03.03.05.ODP[01]: frequency] for indications and the potential impact of inappropriate or unusual activity. b. Report findings to organizational personnel or roles. c. Analyze and correlate audit records across different repositories to gain organization-wide situational awareness. | E24: =COUNTIF(ODPs!$C$2:$C$89,B24) -> 1 | F24: =COUNTIF(Objectives!$C$2:$C$423,B24) -> 4 | G24: Examine, Interview, Test | J24: Not started
A25: Audit and Accountability | B25: 03.03.06 | C25: Audit Record Reduction and Report Generation | D25: a. Implement an audit record reduction and report generation capability that supports audit record review, analysis, reporting requirements, and after-the-fact investigations of incidents. b. Preserve the original content and time ordering of audit records. | E25: =COUNTIF(ODPs!$C$2:$C$89,B25) -> 0 | F25: =COUNTIF(Objectives!$C$2:$C$423,B25) -> 6 | G25: Examine, Interview, Test | J25: Not started
A26: Audit and Accountability | B26: 03.03.07 | C26: Time Stamps | D26: a. Use internal system clocks to generate time stamps for audit records. b. Record time stamps for audit records that meet [A.03.03.07.ODP[01]: granularity of time measurement] and that use Coordinated Universal Time (UTC), have a fixed local time offset from UTC, or include the local time offset as part of the time stamp. | E26: =COUNTIF(ODPs!$C$2:$C$89,B26) -> 1 | F26: =COUNTIF(Objectives!$C$2:$C$423,B26) -> 3 | G26: Examine, Interview, Test | J26: Not started
A27: Audit and Accountability | B27: 03.03.08 | C27: Protection of Audit Information | D27: a. Protect audit information and audit logging tools from unauthorized access, modification, and deletion. b. Authorize access to management of audit logging functionality to only a subset of privileged users or roles. | E27: =COUNTIF(ODPs!$C$2:$C$89,B27) -> 0 | F27: =COUNTIF(Objectives!$C$2:$C$423,B27) -> 3 | G27: Examine, Interview, Test | J27: Not started
A28: Configuration Management | B28: 03.04.01 | C28: Baseline Configuration | D28: a. Develop and maintain under configuration control, a current baseline configuration of the system. b. Review and update the baseline configuration of the system [A.03.04.01.ODP[01]: frequency] and when system components are installed or modified. | E28: =COUNTIF(ODPs!$C$2:$C$89,B28) -> 1 | F28: =COUNTIF(Objectives!$C$2:$C$423,B28) -> 6 | G28: Examine, Interview, Test | J28: Not started
A29: Configuration Management | B29: 03.04.02 | C29: Configuration Settings | D29: a. Establish, document, and implement the following configuration settings for the system that reflect the most restrictive mode consistent with operational requirements: [A.03.04.02.ODP[01]: configuration settings] . b. Identify, document, and approve any deviations from established configuration settings. | E29: =COUNTIF(ODPs!$C$2:$C$89,B29) -> 1 | F29: =COUNTIF(Objectives!$C$2:$C$423,B29) -> 4 | G29: Examine, Interview, Test | J29: Not started
... A86: System and Information Integrity | B86: 03.14.02 | C86: Malicious Code Protection | D86: a. Implement malicious code protection mechanisms at system entry and exit points to detect and eradicate malicious code. b. Update malicious code protection mechanisms as new releases are available in accordance with configuration management policies and procedures. c. Configure malicious code protection mechanisms to: 1. Perform scans of the system [A.03.14.02.ODP[01]: frequency] and real-time scans of files from external sources at endpoints or system entry and exit points as the files are downloaded, opened, or executed; and 2. Block malicious code, quarantine malicious code, or take other mitigation actions in response to malicious code detection. | E86: =COUNTIF(ODPs!$C$2:$C$89,B86) -> 1 | F86: =COUNTIF(Objectives!$C$2:$C$423,B86) -> 6 | G86: Examine, Interview, Test | J86: Not started
A87: System and Information Integrity | B87: 03.14.03 | C87: Security Alerts, Advisories, and Directives | D87: a. Receive system security alerts, advisories, and directives from external organizations on an ongoing basis. b. Generate and disseminate internal system security alerts, advisories, and directives, as necessary. | E87: =COUNTIF(ODPs!$C$2:$C$89,B87) -> 0 | F87: =COUNTIF(Objectives!$C$2:$C$423,B87) -> 3 | J87: Not started
A88: System and Information Integrity | B88: 03.14.06 | C88: System Monitoring | D88: a. Monitor the system to detect: 1. Attacks and indicators of potential attacks and 2. Unauthorized connections. b. Identify unauthorized use of the system. c. Monitor inbound and outbound communications traffic to detect unusual or unauthorized activities or conditions. | E88: =COUNTIF(ODPs!$C$2:$C$89,B88) -> 0 | F88: =COUNTIF(Objectives!$C$2:$C$423,B88) -> 6 | G88: Examine, Interview, Test | J88: Not started
A89: System and Information Integrity | B89: 03.14.08 | C89: Information Management and Retention | D89: Manage and retain CUI within the system and CUI output from the system in accordance with applicable laws, Executive Orders, directives, regulations, policies, standards, guidelines, and operational requirements. | E89: =COUNTIF(ODPs!$C$2:$C$89,B89) -> 0 | F89: =COUNTIF(Objectives!$C$2:$C$423,B89) -> 4 | G89: Examine, Interview, Test | J89: Not started
A90: Planning | B90: 03.15.01 | C90: Policy and Procedures | D90: a. Develop, document, and disseminate to organizational personnel or roles the policies and procedures needed to satisfy the security requirements for the protection of CUI. b. Review and update policies and procedures [A.03.15.01.ODP[01]: frequency]. | E90: =COUNTIF(ODPs!$C$2:$C$89,B90) -> 1 | F90: =COUNTIF(Objectives!$C$2:$C$423,B90) -> 6 | G90: Examine, Interview | J90: Not started
A91: Planning | B91: 03.15.02 | C91: System Security Plan | D91: a. Develop a system security plan that: 1. Defines the constituent system components; 2. Identifies the information types processed, stored, and transmitted by the system; 3. Describes specific threats to the system that are of concern to the organization; 4. Describes the operational environment for the system and any dependencies on or connections to other systems or system components; 5. Provides an overview of the security requirements for the system; 6. Describes the safeguards in place or planned for meeting the security requirements; 7. Identifies individuals that fulfill system roles and responsibilities; and 8. Includes other relevant information necessary for the protection of CUI. b. Review and update the system security plan [A.03.15.02.ODP[01]: frequency]. c. Protect the system security plan from unauthorized disclosure. | E91: =COUNTIF(ODPs!$C$2:$C$89,B91) -> 1 | F91: =COUNTIF(Objectives!$C$2:$C$423,B91) -> 11 | G91: Examine, Interview, Test | J91: Not started
A92: Planning | B92: 03.15.03 | C92: Rules of Behavior | D92: a. Establish rules that describe the responsibilities and expected behavior for system usage and protecting CUI. b. Provide rules to individuals who require access to the system. c. Receive a documented acknowledgement from individuals indicating that they have read, understand, and agree to abide by the rules of behavior before authorizing access to CUI and the system. d. Review and update the rules of behavior [A.03.15.03.ODP[01]: frequency]. | E92: =COUNTIF(ODPs!$C$2:$C$89,B92) -> 1 | F92: =COUNTIF(Objectives!$C$2:$C$423,B92) -> 5 | G92: Examine, Interview, Test | J92: Not started
A93: System and Services Acquisition | B93: 03.16.01 | C93: Security Engineering Principles | D93: Apply the following systems security engineering principles to the development or modification of the system and system components: [A.03.16.01.ODP[01]: systems security engineering principles]. | E93: =COUNTIF(ODPs!$C$2:$C$89,B93) -> 1 | F93: =COUNTIF(Objectives!$C$2:$C$423,B93) -> 1 | G93: Examine, Interview, Test | J93: Not started
A94: System and Services Acquisition | B94: 03.16.02 | C94: Unsupported System Components | D94: a. Replace system components when support for the components is no longer available from the developer, vendor, or manufacturer. b. Provide options for risk mitigation or alternative sources for continued support for unsupported components that cannot be replaced. | E94: =COUNTIF(ODPs!$C$2:$C$89,B94) -> 0 | F94: =COUNTIF(Objectives!$C$2:$C$423,B94) -> 2 | G94: Examine, Interview, Test | J94: Not started
A95: System and Services Acquisition | B95: 03.16.03 | C95: External System Services | D95: a. Require the providers of external system services used for the processing, storage, or transmission of CUI to comply with the following security requirements: [A.03.16.03.ODP[01]: security requirements]. b. Define and document user roles and responsibilities with regard to external system services, including shared responsibilities with external service providers. c. Implement processes, methods, and techniques to monitor security requirement compliance by external service providers on an ongoing basis. | E95: =COUNTIF(ODPs!$C$2:$C$89,B95) -> 1 | F95: =COUNTIF(Objectives!$C$2:$C$423,B95) -> 3 | G95: Examine, Interview, Test | J95: Not started
A96: Supply Chain Risk Management | B96: 03.17.01 | C96: Supply Chain Risk Management Plan | D96: a. Develop a plan for managing supply chain risks associated with the research and development, design, manufacturing, acquisition, delivery, integration, operations, maintenance, and disposal of the system, system components, or system services. b. Review and update the supply chain risk management plan [A.03.17.01.ODP[01]: frequency]. c. Protect the supply chain risk management plan from unauthorized disclosure. | E96: =COUNTIF(ODPs!$C$2:$C$89,B96) -> 1 | F96: =COUNTIF(Objectives!$C$2:$C$423,B96) -> 13 | G96: Examine, Interview, Test | J96: Not started
A97: Supply Chain Risk Management | B97: 03.17.02 | C97: Acquisition Strategies, Tools, and Methods | D97: Develop and implement acquisition strategies, contract tools, and procurement methods to identify, protect against, and mitigate supply chain risks. | E97: =COUNTIF(ODPs!$C$2:$C$89,B97) -> 0 | F97: =COUNTIF(Objectives!$C$2:$C$423,B97) -> 6 | G97: Examine, Interview, Test | J97: Not started
A98: Supply Chain Risk Management | B98: 03.17.03 | C98: Supply Chain Requirements and Processes | D98: a. Establish a process for identifying and addressing weaknesses or deficiencies in the supply chain elements and processes. b. Enforce the following security requirements to protect against supply chain risks to the system, system components, or system services and to limit the harm or consequences from supply chain-related events: [A.03.17.03.ODP[01]: security requirements]. | E98: =COUNTIF(ODPs!$C$2:$C$89,B98) -> 1 | F98: =COUNTIF(Objectives!$C$2:$C$423,B98) -> 3 | G98: Examine, Interview, Test | J98: Not started

Sheet ODPs
A1: ODP ID | B1: Family | C1: Req ID | D1: Requirement title | E1: Parameter type | F1: What must be defined (NIST) | G1: Choices NIST lists (if any) | H1: Objectives that depend on it | I1: Value defined | J1: Decided by | K1: Date decided | L1: Basis for the value | M1: Status
A2: A.03.01.01.ODP[01] | B2: Access Control | C2: 03.01.01 | D2: Account Management | E2: time period | F2: the time period for account inactivity before disabling is defined. | H2: 1 | M2: Not defined
A3: A.03.01.01.ODP[02] | B3: Access Control | C3: 03.01.01 | D3: Account Management | E3: time period | F3: the time period within which to notify account managers and designated personnel or roles when accounts are no longer required is defined. | H3: 1 | M3: Not defined
A4: A.03.01.01.ODP[03] | B4: Access Control | C4: 03.01.01 | D4: Account Management | E4: time period | F4: the time period within which to notify account managers and designated personnel or roles when users are terminated or transferred is defined. | H4: 1 | M4: Not defined
A5: A.03.01.01.ODP[04] | B5: Access Control | C5: 03.01.01 | D5: Account Management | E5: time period | F5: the time period within which to notify account managers and designated personnel or roles when system usage or the need-to-know changes for an individual is defined. | H5: 1 | M5: Not defined
A6: A.03.01.01.ODP[05] | B6: Access Control | C6: 03.01.01 | D6: Account Management | E6: time period | F6: the time period of expected inactivity requiring users to log out of the system is defined. | H6: 1 | M6: Not defined
A7: A.03.01.01.ODP[06] | B7: Access Control | C7: 03.01.01 | D7: Account Management | E7: circumstances | F7: circumstances requiring users to log out of the system are defined. | H7: 1 | M7: Not defined
A8: A.03.01.05.ODP[01] | B8: Access Control | C8: 03.01.05 | D8: Least Privilege | E8: security functions | F8: security functions for authorized access are defined. | H8: 1 | M8: Not defined
A9: A.03.01.05.ODP[02] | B9: Access Control | C9: 03.01.05 | D9: Least Privilege | E9: security-relevant information | F9: security-relevant information for authorized access is defined. | H9: 1 | M9: Not defined
A10: A.03.01.05.ODP[03] | B10: Access Control | C10: 03.01.05 | D10: Least Privilege | E10: frequency | F10: the frequency at which to review the privileges assigned to roles or classes of users is defined. | H10: 1 | M10: Not defined
A11: A.03.01.06.ODP[01] | B11: Access Control | C11: 03.01.06 | D11: Least Privilege – Privileged Accounts | E11: personnel or roles | F11: personnel or roles to which privileged accounts on the system are to be restricted are defined. | H11: 1 | M11: Not defined
A12: A.03.01.08.ODP[01] | B12: Access Control | C12: 03.01.08 | D12: Unsuccessful Logon Attempts | E12: number | F12: the number of consecutive invalid logon attempts by a user allowed during a time period is defined. | H12: 1 | M12: Not defined
A13: A.03.01.08.ODP[02] | B13: Access Control | C13: 03.01.08 | D13: Unsuccessful Logon Attempts | E13: time period | F13: the time period to which the number of consecutive invalid logon attempts by a user is limited is defined. | H13: 1 | M13: Not defined
A14: A.03.01.08.ODP[03] | B14: Access Control | C14: 03.01.08 | D14: Unsuccessful Logon Attempts | E14: SELECTED PARAMETER VALUES | G14: lock the account or node for an {{ insert: param, A.03.01.08.ODP.04 }}; lock the account or node until released by an administrator; delay next logon prompt; notify system administrator; take other action | H14: 1 | M14: Not defined
A15: A.03.01.08.ODP[04] | B15: Access Control | C15: 03.01.08 | D15: Unsuccessful Logon Attempts | E15: time period | F15: the time period for an account or node to be locked is defined (if selected). | H15: 0 | M15: Not defined
A16: A.03.01.10.ODP[01] | B16: Access Control | C16: 03.01.10 | D16: Device Lock | E16: SELECTED PARAMETER VALUES | G16: initiating a device lock after {{ insert: param, A.03.01.10.ODP.02 }} of inactivity; requiring the user to initiate a device lock before leaving the system unattended | H16: 1 | M16: Not defined
A17: A.03.01.10.ODP[02] | B17: Access Control | C17: 03.01.10 | D17: Device Lock | E17: time period | F17: the time period of inactivity after which a device lock is initiated is defined (if selected). | H17: 0 | M17: Not defined
A18: A.03.01.11.ODP[01] | B18: Access Control | C18: 03.01.11 | D18: Session Termination | E18: conditions or trigger events | F18: conditions or trigger events that require session disconnect are defined. | H18: 1 | M18: Not defined
A19: A.03.01.20.ODP[01] | B19: Access Control | C19: 03.01.20 | D19: Use of External Systems | E19: security requirements | F19: security requirements to be satisfied on external systems prior to allowing the use of or access to those systems by authorized individuals are defined. | H19: 1 | M19: Not defined
A20: A.03.02.01.ODP[01] | B20: Awareness and Training | C20: 03.02.01 | D20: Literacy Training and Awareness | E20: frequency | F20: the frequency at which to provide security literacy training to system users after initial training is defined. | H20: 1 | M20: Not defined
A21: A.03.02.01.ODP[02] | B21: Awareness and Training | C21: 03.02.01 | D21: Literacy Training and Awareness | E21: events | F21: events that require security literacy training for system users are defined. | H21: 1 | M21: Not defined
A22: A.03.02.01.ODP[03] | B22: Awareness and Training | C22: 03.02.01 | D22: Literacy Training and Awareness | E22: frequency | F22: the frequency at which to update security literacy training content is defined. | H22: 1 | M22: Not defined
A23: A.03.02.01.ODP[04] | B23: Awareness and Training | C23: 03.02.01 | D23: Literacy Training and Awareness | E23: events | F23: events that require security literacy training content updates are defined. | H23: 1 | M23: Not defined
A24: A.03.02.02.ODP[01] | B24: Awareness and Training | C24: 03.02.02 | D24: Role-Based Training | E24: frequency | F24: the frequency at which to provide role-based security training to assigned personnel after initial training is defined. | H24: 1 | M24: Not defined
A25: A.03.02.02.ODP[02] | B25: Awareness and Training | C25: 03.02.02 | D25: Role-Based Training | E25: events | F25: events that require role-based security training are defined. | H25: 1 | M25: Not defined
A26: A.03.02.02.ODP[03] | B26: Awareness and Training | C26: 03.02.02 | D26: Role-Based Training | E26: frequency | F26: the frequency at which to update role-based security training content is defined. | H26: 1 | M26: Not defined
A27: A.03.02.02.ODP[04] | B27: Awareness and Training | C27: 03.02.02 | D27: Role-Based Training | E27: events | F27: events that require role-based security training content updates are defined. | H27: 1 | M27: Not defined
A28: A.03.03.01.ODP[01] | B28: Audit and Accountability | C28: 03.03.01 | D28: Event Logging | E28: event types | F28: event types selected for logging within the system are defined. | H28: 1 | M28: Not defined
... A73: A.03.12.01.ODP[01] | B73: Security Assessment and Monitoring | C73: 03.12.01 | D73: Security Assessment | E73: frequency | F73: the frequency at which to assess the security requirements for the system and its environment of operation is defined. | H73: 1 | M73: Not defined
A74: A.03.12.05.ODP[01] | B74: Security Assessment and Monitoring | C74: 03.12.05 | D74: Information Exchange | E74: SELECTED PARAMETER VALUES | G74: interconnection security agreements; information exchange security agreements; memoranda of understanding or agreement; service-level agreements; user agreements; non-disclosure agreements; other types of agreements | H74: 2 | M74: Not defined
A75: A.03.12.05.ODP[02] | B75: Security Assessment and Monitoring | C75: 03.12.05 | D75: Information Exchange | E75: frequency | F75: the frequency at which to review and update agreements is defined. | H75: 2 | M75: Not defined
A76: A.03.13.09.ODP[01] | B76: System and Communications Protection | C76: 03.13.09 | D76: Network Disconnect | E76: time period | F76: the time period of inactivity after which the system terminates a network connection associated with a communications session is defined. | H76: 1 | M76: Not defined
A77: A.03.13.10.ODP[01] | B77: System and Communications Protection | C77: 03.13.10 | D77: Cryptographic Key Establishment and Management | E77: requirements | F77: requirements for key generation, distribution, storage, access, and destruction are defined. | H77: 2 | M77: Not defined
A78: A.03.13.11.ODP[01] | B78: System and Communications Protection | C78: 03.13.11 | D78: Cryptographic Protection | E78: types of cryptography | F78: the types of cryptography for protecting the confidentiality of CUI are defined. | H78: 1 | M78: Not defined
A79: A.03.13.12.ODP[01] | B79: System and Communications Protection | C79: 03.13.12 | D79: Collaborative Computing Devices and Applications | E79: exceptions | F79: exceptions where remote activation is to be allowed are defined. | H79: 1 | M79: Not defined
A80: A.03.14.01.ODP[01] | B80: System and Information Integrity | C80: 03.14.01 | D80: Flaw Remediation | E80: time period | F80: the time period within which to install security-relevant software updates after the release of the updates is defined. | H80: 1 | M80: Not defined
A81: A.03.14.01.ODP[02] | B81: System and Information Integrity | C81: 03.14.01 | D81: Flaw Remediation | E81: time period | F81: the time period within which to install security-relevant firmware updates after the release of the updates is defined. | H81: 1 | M81: Not defined
A82: A.03.14.02.ODP[01] | B82: System and Information Integrity | C82: 03.14.02 | D82: Malicious Code Protection | E82: frequency | F82: the frequency at which malicious code protection mechanisms perform scans is defined. | H82: 1 | M82: Not defined
A83: A.03.15.01.ODP[01] | B83: Planning | C83: 03.15.01 | D83: Policy and Procedures | E83: frequency | F83: the frequency at which the policies and procedures for satisfying security requirements are reviewed and updated is defined. | H83: 2 | M83: Not defined
A84: A.03.15.02.ODP[01] | B84: Planning | C84: 03.15.02 | D84: System Security Plan | E84: frequency | F84: the frequency at which the system security plan is reviewed and updated is defined. | H84: 2 | M84: Not defined
...

Sheet Objectives
A1: Objective ID | B1: Family | C1: Req ID | D1: Requirement title | E1: Requirement item | F1: What is measured (SP 800-171A Rev 3 objective) | G1: Depends on ODP(s) | H1: Result | I1: Method used | J1: Evidence reference | K1: Assessor | L1: Date assessed | M1: Notes
A2: A.03.01.01.a.01 | B2: Access Control | C2: 03.01.01 | D2: Account Management | E2: 03.01.01.a | F2: system account types allowed are defined. | H2: Not assessed
A3: A.03.01.01.a.02 | B3: Access Control | C3: 03.01.01 | D3: Account Management | E3: 03.01.01.a | F3: system account types prohibited are defined. | H3: Not assessed
A4: A.03.01.01.b.01 | B4: Access Control | C4: 03.01.01 | D4: Account Management | E4: 03.01.01.b | F4: system accounts are created in accordance with organizational policy, procedures, prerequisites, and criteria. | H4: Not assessed
A5: A.03.01.01.b.02 | B5: Access Control | C5: 03.01.01 | D5: Account Management | E5: 03.01.01.b | F5: system accounts are enabled in accordance with organizational policy, procedures, prerequisites, and criteria. | H5: Not assessed
A6: A.03.01.01.b.03 | B6: Access Control | C6: 03.01.01 | D6: Account Management | E6: 03.01.01.b | F6: system accounts are modified in accordance with organizational policy, procedures, prerequisites, and criteria. | H6: Not assessed
A7: A.03.01.01.b.04 | B7: Access Control | C7: 03.01.01 | D7: Account Management | E7: 03.01.01.b | F7: system accounts are disabled in accordance with organizational policy, procedures, prerequisites, and criteria. | H7: Not assessed
A8: A.03.01.01.b.05 | B8: Access Control | C8: 03.01.01 | D8: Account Management | E8: 03.01.01.b | F8: system accounts are removed in accordance with organizational policy, procedures, prerequisites, and criteria. | H8: Not assessed
A9: A.03.01.01.c.01 | B9: Access Control | C9: 03.01.01 | D9: Account Management | E9: 03.01.01.c.01 | F9: authorized users of the system are specified. | H9: Not assessed
A10: A.03.01.01.c.02 | B10: Access Control | C10: 03.01.01 | D10: Account Management | E10: 03.01.01.c.02 | F10: group and role memberships are specified. | H10: Not assessed
A11: A.03.01.01.c.03 | B11: Access Control | C11: 03.01.01 | D11: Account Management | E11: 03.01.01.c.03 | F11: access authorizations (i.e., privileges) for each account are specified. | H11: Not assessed
A12: A.03.01.01.d.01 | B12: Access Control | C12: 03.01.01 | D12: Account Management | E12: 03.01.01.d.01 | F12: access to the system is authorized based on a valid access authorization. | H12: Not assessed
A13: A.03.01.01.d.02 | B13: Access Control | C13: 03.01.01 | D13: Account Management | E13: 03.01.01.d.02 | F13: access to the system is authorized based on intended system usage. | H13: Not assessed
... A15: A.03.01.01.f.01 | B15: Access Control | C15: 03.01.01 | D15: Account Management | E15: 03.01.01.f.01 | F15: system accounts are disabled when the accounts have expired. | H15: Not assessed
A16: A.03.01.01.f.02 | B16: Access Control | C16: 03.01.01 | D16: Account Management | E16: 03.01.01.f.02 | F16: system accounts are disabled when the accounts have been inactive for [A.03.01.01.ODP[01]: time period]. | G16: A.03.01.01.ODP[01] | H16: Not assessed
A17: A.03.01.01.f.03 | B17: Access Control | C17: 03.01.01 | D17: Account Management | E17: 03.01.01.f.03 | F17: system accounts are disabled when the accounts are no longer associated with a user or individual. | H17: Not assessed
A18: A.03.01.01.f.04 | B18: Access Control | C18: 03.01.01 | D18: Account Management | E18: 03.01.01.f.04 | F18: system accounts are disabled when the accounts violate organizational policy. | H18: Not assessed
A19: A.03.01.01.f.05 | B19: Access Control | C19: 03.01.01 | D19: Account Management | E19: 03.01.01.f.05 | F19: system accounts are disabled when significant risks associated with individuals are discovered. | H19: Not assessed
A20: A.03.01.01.g.01 | B20: Access Control | C20: 03.01.01 | D20: Account Management | E20: 03.01.01.g.01 | F20: account managers and designated personnel or roles are notified within [A.03.01.01.ODP[02]: time period] when accounts are no longer required. | G20: A.03.01.01.ODP[02] | H20: Not assessed
A21: A.03.01.01.g.02 | B21: Access Control | C21: 03.01.01 | D21: Account Management | E21: 03.01.01.g.02 | F21: account managers and designated personnel or roles are notified within [A.03.01.01.ODP[03]: time period] when users are terminated or transferred. | G21: A.03.01.01.ODP[03] | H21: Not assessed
A22: A.03.01.01.g.03 | B22: Access Control | C22: 03.01.01 | D22: Account Management | E22: 03.01.01.g.03 | F22: account managers and designated personnel or roles are notified within [A.03.01.01.ODP[04]: time period] when system usage or the need-to-know changes for an individual. | G22: A.03.01.01.ODP[04] | H22: Not assessed
A23: A.03.01.01.h | B23: Access Control | C23: 03.01.01 | D23: Account Management | E23: 03.01.01.h | F23: users are required to log out of the system after [A.03.01.01.ODP[05]: time period] of expected inactivity or when the following circumstances occur: [A.03.01.01.ODP[06]: circumstances]. | G23: A.03.01.01.ODP[05], A.03.01.01.ODP[06] | H23: Not assessed
A24: A.03.01.02.01 | B24: Access Control | C24: 03.01.02 | D24: Access Enforcement | E24: 03.01.02 (whole requirement) | F24: approved authorizations for logical access to CUI are enforced in accordance with applicable access control policies. | H24: Not assessed
A25: A.03.01.02.02 | B25: Access Control | C25: 03.01.02 | D25: Access Enforcement | E25: 03.01.02 (whole requirement) | F25: approved authorizations for logical access to system resources are enforced in accordance with applicable access control policies. | H25: Not assessed
A26: A.03.01.03.01 | B26: Access Control | C26: 03.01.03 | D26: Information Flow Enforcement | E26: 03.01.03 (whole requirement) | F26: approved authorizations are enforced for controlling the flow of CUI within the system. | H26: Not assessed
A27: A.03.01.03.02 | B27: Access Control | C27: 03.01.03 | D27: Information Flow Enforcement | E27: 03.01.03 (whole requirement) | F27: approved authorizations are enforced for controlling the flow of CUI between connected systems. | H27: Not assessed
A28: A.03.01.04.a | B28: Access Control | C28: 03.01.04 | D28: Separation of Duties | E28: 03.01.04.a | F28: duties of individuals requiring separation are identified. | H28: Not assessed
A29: A.03.01.04.b | B29: Access Control | C29: 03.01.04 | D29: Separation of Duties | E29: 03.01.04.b | F29: system access authorizations to support separation of duties are defined. | H29: Not assessed
A30: A.03.01.05.a | B30: Access Control | C30: 03.01.05 | D30: Least Privilege | E30: 03.01.05.a | F30: system access for users (or processes acting on behalf of users) is authorized only when necessary to accomplish assigned organizational tasks. | H30: Not assessed
A31: A.03.01.05.b.01 | B31: Access Control | C31: 03.01.05 | D31: Least Privilege | E31: 03.01.05.b | F31: access to [A.03.01.05.ODP[01]: security functions] is authorized. | G31: A.03.01.05.ODP[01] | H31: Not assessed
A32: A.03.01.05.b.02 | B32: Access Control | C32: 03.01.05 | D32: Least Privilege | E32: 03.01.05.b | F32: access to [A.03.01.05.ODP[02]: security-relevant information] is authorized. | G32: A.03.01.05.ODP[02] | H32: Not assessed
A33: A.03.01.05.c | B33: Access Control | C33: 03.01.05 | D33: Least Privilege | E33: 03.01.05.c | F33: the privileges assigned to roles or classes of users are reviewed [A.03.01.05.ODP[03]: frequency] to validate the need for such privileges. | G33: A.03.01.05.ODP[03] | H33: Not assessed
A34: A.03.01.05.d | B34: Access Control | C34: 03.01.05 | D34: Least Privilege | E34: 03.01.05.d | F34: privileges are reassigned or removed, as necessary. | H34: Not assessed
A35: A.03.01.06.a | B35: Access Control | C35: 03.01.06 | D35: Least Privilege – Privileged Accounts | E35: 03.01.06.a | F35: privileged accounts on the system are restricted to [A.03.01.06.ODP[01]: personnel or roles]. | G35: A.03.01.06.ODP[01] | H35: Not assessed
A36: A.03.01.06.b | B36: Access Control | C36: 03.01.06 | D36: Least Privilege – Privileged Accounts | E36: 03.01.06.b | F36: users (or roles) with privileged accounts are required to use non-privileged accounts when accessing non-security functions or non-security information. | H36: Not assessed
A37: A.03.01.07.a | B37: Access Control | C37: 03.01.07 | D37: Least Privilege – Privileged Functions | E37: 03.01.07.a | F37: non-privileged users are prevented from executing privileged functions. | H37: Not assessed
A38: A.03.01.07.b | B38: Access Control | C38: 03.01.07 | D38: Least Privilege – Privileged Functions | E38: 03.01.07.b | F38: the execution of privileged functions is logged. | H38: Not assessed
A39: A.03.01.08.a | B39: Access Control | C39: 03.01.08 | D39: Unsuccessful Logon Attempts | E39: 03.01.08.a | F39: a limit of [A.03.01.08.ODP[01]: number] consecutive invalid logon attempts by a user during [A.03.01.08.ODP[02]: time period] is enforced. | G39: A.03.01.08.ODP[01], A.03.01.08.ODP[02] | H39: Not assessed
A40: A.03.01.08.b | B40: Access Control | C40: 03.01.08 | D40: Unsuccessful Logon Attempts | E40: 03.01.08.b | F40: [A.03.01.08.ODP[03]: SELECTED PARAMETER VALUES] when the maximum number of unsuccessful attempts is exceeded. | G40: A.03.01.08.ODP[03] | H40: Not assessed
A41: A.03.01.09 | B41: Access Control | C41: 03.01.09 | D41: System Use Notification | E41: 03.01.09 (whole requirement) | F41: a system use notification message with privacy and security notices consistent with applicable CUI rules is displayed before granting access to the system. | H41: Not assessed
...

Sheet Methods
A1: Req ID | B1: Family | C1: Requirement title | D1: Method | E1: Things to examine / people to interview / items to test
A2: 03.01.01 | B2: Access Control | C2: Account Management | D2: Examine | E2: • access control policy and procedures • personnel termination or transfer policies and procedures • procedures for account management • list of active system accounts and the name of the individual associated with each account • system design documentation • list of conditions for group and role membership • system configuration settings • notifications of recent transfers, separations, or terminations of employees • list of recently disabled system accounts and the name of the individual associated with each account • list of user activities that pose significant organizational risks • access authorization records • account management compliance reviews • system monitoring and audit records • system security plan • system-generated list of accounts removed • system-generated list of emergency accounts disabled • system-generated list of disabled accounts • other relevant documents and records
A3: 03.01.01 | B3: Access Control | C3: Account Management | D3: Interview | E3: • personnel with account management responsibilities • system administrators • personnel with information security responsibilities • system developers
A4: 03.01.01 | B4: Access Control | C4: Account Management | D4: Test | E4: • processes for account management on the system • mechanisms for implementing account management
A5: 03.01.02 | B5: Access Control | C5: Access Enforcement | D5: Examine | E5: • access control policy and procedures • procedures for access enforcement • system design documentation • system configuration settings • list of approved authorizations (i.e., user privileges) • system audit records • system security plan • other relevant documents or records
A6: 03.01.02 | B6: Access Control | C6: Access Enforcement | D6: Interview | E6: • personnel with access enforcement responsibilities • system administrators • personnel with information security responsibilities • system developers
A7: 03.01.02 | B7: Access Control | C7: Access Enforcement | D7: Test | E7: • mechanisms for implementing the access control policy
A8: 03.01.03 | B8: Access Control | C8: Information Flow Enforcement | D8: Examine | E8: • access control policy and procedures • information flow control policies • procedures for information flow enforcement • security architecture and design documentation • system configuration settings • system baseline configuration • system audit records • list of information flow authorizations • system security plan • other relevant documents or records
A9: 03.01.03 | B9: Access Control | C9: Information Flow Enforcement | D9: Interview | E9: • system administrators • personnel with security architecture responsibilities • personnel with information security responsibilities • system developers
A10: 03.01.03 | B10: Access Control | C10: Information Flow Enforcement | D10: Test | E10: • mechanisms for implementing the information flow enforcement policy
A11: 03.01.04 | B11: Access Control | C11: Separation of Duties | D11: Examine | E11: • access control policy and procedures • procedures for the separation of duties and the division of responsibilities • system configuration settings • system audit records • system access authorizations • list of divisions of responsibility and separation of duties • system security plan • other relevant documents or records
A12: 03.01.04 | B12: Access Control | C12: Separation of Duties | D12: Interview | E12: • personnel with responsibilities for defining the separation of duties and the division of responsibilities • personnel with information security responsibilities • system administrators
... A282: 03.17.03 | B282: Supply Chain Risk Management | C282: Supply Chain Requirements and Processes | D282: Test | E282: • processes for identifying and addressing supply chain element and process deficiencies

Sheet Withdrawn
A1: Req ID | B1: Family | C1: Status | D1: Where it went (per NIST)
A2: 03.01.13 | B2: Access Control | C2: withdrawn | D2: Addressed by 03.13.08
A3: 03.01.14 | B3: Access Control | C3: withdrawn | D3: Incorporated into 03.01.12
A4: 03.01.15 | B4: Access Control | C4: withdrawn | D4: Incorporated into 03.01.12
A5: 03.01.17 | B5: Access Control | C5: withdrawn | D5: Incorporated into 03.01.16
A6: 03.01.19 | B6: Access Control | C6: withdrawn | D6: Incorporated into 03.01.18
A7: 03.01.21 | B7: Access Control | C7: withdrawn | D7: Incorporated into 03.01.20
A8: 03.02.03 | B8: Awareness and Training | C8: withdrawn | D8: Incorporated into 03.02.01
A9: 03.03.09 | B9: Audit and Accountability | C9: withdrawn | D9: Incorporated into 03.03.08
A10: 03.04.07 | B10: Configuration Management | C10: withdrawn | D10: Incorporated into 03.04.06
A11: 03.04.09 | B11: Configuration Management | C11: withdrawn | D11: Addressed by 03.01.05
A12: 03.05.06 | B12: Identification and Authentication | C12: withdrawn
A13: 03.05.08 | B13: Identification and Authentication | C13: withdrawn
A14: 03.05.09 | B14: Identification and Authentication | C14: withdrawn
A15: 03.05.10 | B15: Identification and Authentication | C15: withdrawn | D15: Incorporated into 03.05.07
A16: 03.07.01 | B16: Maintenance | C16: withdrawn
